Workbook

Sheet GESTIONE
C2: BAR 1 | I2: BAR PREMIUM | O2: CAMBUSA 1 | T2: CONTANTE PRELEVATO
C3: TIPOLOGIA | D3: PREZZO | E3: N° | F3: TOTALI | I3: TIPOLOGIA | J3: PREZZO | K3: N° | L3: TOTALI | O3: CONTANTE | P3: SOSPESO | Q3: POS | R3: TOTALE | T3: =E10+E11+E12+E13+Q5+Q6+Q7+Q8+Q9+Q10+Q11+Q32+Q33+Q34+Q35+Q36+Q37+Q38+E37+E38+E39+E40 -> 0
C4: I CONSUMAZIONE | D4: 15 | E4: 0 | F4: =D4*E4 -> 0 | I4: I CONSUMAZIONE | J4: 15 | K4: 0 | L4: =J4*K4 -> 0 | O4: 0 | P4: 0 | Q4: 0 | R4: =O4+P4+Q4 -> 0
C5: ACQUA | D5: 3 | E5: 0 | F5: =D5*E5 -> 0 | I5: ACQUA | J5: 3 | K5: 0 | L5: =J5*K5 -> 0 | O5: PRELIEVO 1 | Q5: 0 | T5: SPESE PAGATE
C6: II CONSUMAZIONE | D6: 10 | E6: 0 | F6: =D6*E6 -> 0 | I6: II CONSUMAZIONE | J6: 10 | K6: 0 | L6: =J6*K6 -> 0 | O6: PRELIEVO 2 | Q6: 0 | T6: =F76+F77+F105+K105+L91+E79+(E74-D56) -> 4040
C7: CICCHETTO | D7: 5 | E7: 0 | F7: =D7*E7 -> 0 | I7: CICCHETTO | J7: 5 | K7: 0 | L7: =J7*K7 -> 0 | O7: PRELIEVO 3 | Q7: 0
C8: PREMIUM | D8: 15 | E8: 0 | F8: =D8*E8 -> 0 | I8: PREMIUM | J8: 15 | K8: 0 | L8: =J8*K8 -> 0 | O8: POS | Q8: 0 | T8: RIMANENZA CASH
C9: INGRESSO TAVOLO | D9: 20 | E9: 0 | F9: =D9*E9 -> 0 | I9: INGRESSO TAVOLO | J9: 20 | K9: 0 | L9: =J9*K9 -> 0 | O9: SOSPESO | Q9: 0 | T9: =T3-T6-Q4-Q31-D15-D42 -> -4040
C10: PRELIEVO 1 | E10: 0 | I10: PRELIEVO 1 | K10: 0 | O10: PRELIEVO 6 | Q10: 0
C11: PRELIEVO 2 | E11: 0 | I11: PRELIEVO 2 | K11: 0 | O11: PRELIEVO 7 | Q11: 0
C12: PRELIEVO 3 | E12: 0 | I12: PRELIEVO 3 | K12: 0 | O12: SALDO | Q12: =R4-Q5-Q9-Q10-Q11-Q6-Q7-Q8 -> 0
C13: POS | E13: 0 | I13: PRELIEVO 4 | K13: 0
C14: SALDO | E14: =E15-E10-E11-E12-E13 -> 0 | I14: SALDO | K14: =K15-K10-K11-K12-K13 -> 0
C15: Di cui POS | D15: =E13 -> 0 | E15: =SUM(F4:F9) -> 0 | I15: Di cui POS | J15: 0 | K15: =SUM(L4:L9) -> 0
C17: BAR LATERALE | I17: BOTTEGHINO LISTA 2 | O17: TAVOLI CAMBUSA CENTRALE LAURA
C18: TIPOLOGIA | D18: PREZZO | E18: N° | F18: TOTALI | I18: CARD 10 | J18: 10 | L18: =J18*K18 -> 0 | O18: CONTANTE | P18: SOSPESO | Q18: POS | R18: TOTALE
C19: I CONSUMAZIONE | D19: 15 | F19: =D19*E19 -> 0 | I19: CARD 15 | J19: 15 | L19: =J19*K19 -> 0 | O19: 0 | P19: 0 | Q19: 0 | R19: =O19+P19+Q19 -> 0
C20: II CONSUMAZIONE | D20: 10 | F20: =D20*E20 -> 0 | I20: CARD 20 | J20: 20 | L20: =J20*K20 -> 0 | O20: PRELIEVO 1 | Q20: 0
C21: ACQUA | D21: 3 | F21: =D21*E21 -> 0 | I21: CARD 25 | J21: 25 | L21: =J21*K21 -> 0 | O21: PRELIEVO 2 | Q21: 0
C22: PRELIEVO 1 | E22: 0 | I22: PRELIEVO 1 | K22: 0 | O22: PRELIEVO 3 | Q22: 0
C23: PRELIEVO 2 | E23: 0 | I23: PRELIEVO 2 | K23: 0 | O23: PRELIEVO 4 | Q23: 0
C24: PRELIEVO 3 | E24: 0 | I24: PRELIEVO 3 | K24: 0 | O24: SALDO | Q24: =R19-Q20-Q21-Q22-Q23 -> 0
C25: PRELIEVO 4 | E25: 0 | I25: PRELIEVO 4 | K25: 0
C26: SALDO | E26: =E27-E25-E24-E23-E22 -> 0 | I26: SALDO | K26: =K27-K25-K24-K23-K22 -> 0
C27: Di cui POS | D27: 0 | E27: =SUM(F19:F21) -> 0 | I27: Di cui POS | J27: 0 | K27: =L18+L19+L20+L21 -> 0
C29: BAR 2 | I29: BOTTEGHINO TAVOLI 1 MARIA | O29: CAMBUSA 2
C30: TIPOLOGIA | D30: PREZZO | E30: N° | F30: TOTALI | I30: CONTANTE | J30: SOSPESO | K30: POS | L30: TOTALE | O30: CONTANTE | P30: SOSPESO | Q30: POS | R30: TOTALE
C31: I CONSUMAZIONE | D31: 20 | E31: 0 | F31: =D31*E31 -> 0 | L31: =I31+J31+K31 -> 0 | O31: 0 | P31: 0 | Q31: 0 | R31: =O31+P31+Q31 -> 0
C32: ACQUA | D32: 3 | E32: 0 | F32: =D32*E32 -> 0 | O32: PRELIEVO 1 | Q32: 0
C33: I e II CONSUMAZIONE | D33: 10 | E33: 0 | F33: =D33*E33 -> 0 | O33: PRELIEVO 2 | Q33: 0
C34: CICCHETTO | D34: 5 | E34: 0 | F34: =D34*E34 -> 0 | O34: PRELIEVO 3 | Q34: 0
C35: PREMIUM | D35: 15 | E35: 0 | F35: =D35*E35 -> 0 | I35: PRELIEVO 1 | K35: 0 | O35: PRELIEVO 4 | Q35: 0
C36: INGRESSO TVL | D36: 30 | E36: 0 | F36: =D36*E36 -> 0 | I36: PRELIEVO 2 | K36: 0 | O36: PRELIEVO 5 | Q36: 0
C37: PRELIEVO 1 | E37: 0 | I37: PRELIEVO 3 | K37: 0 | O37: PRELIEVO 6 | Q37: 0
C38: PRELIEVO 2 | E38: 0 | I38: PRELIEVO 4 | K38: 0 | O38: PRELIEVO 7 | Q38: 0
C39: POS | E39: 0 | I39: SALDO | K39: =L31-K35-K36-K37-K38 -> 0 | O39: SALDO | Q39: =R31-Q32-Q33-Q34-Q35-Q36-Q37-Q38 -> 0
C40: ONLINE | E40: 0
C41: SALDO | E41: =E42-E40-E39-E38-E37 -> 0
C42: Di cui POS | D42: =E39 -> 0 | E42: =SUM(F31:F36) -> 0
C44: INCASSO | I44: INCASSO | J44: =D57 -> 0 | L44: GRANDI VOCI | O44: CONSUMATO TAVOLI
...

Sheet GUARDAROBA
A1: GUARDAROBA | B1: N° | C1: COSTO | D1: TOTALE
A3: CAPO €5 | B3: 0 | C3: 5 | D3: =B3*C3 -> 0
A4: CAPO €2 | B4: 0 | C4: 2 | D4: =B4*C4 -> 0
C5: TOTALE | D5: =D3+D4 -> 0
A8: PERSONALE
A9: OPERATORE | B9: 5 | C9: 75 | D9: =B9*C9 -> 375
A12: CASSIERE | B12: 2 | C12: 90 | D12: =B12*C12 -> 180
A14: ACCONTO | B14: 0
A15: POS | B15: 0
A16: TOTALE | B16: =B14+B15 -> 0 | C16: NETTO | D16: =D5-D9-D12 -> -555

Sheet RESOCONTO PROPRIETA
A1: RESOCONTO PROPRIETA' 01.01.25
A3: FITTO | B3: =GESTIONE!E74 -> 0
A4: CONSUMATO TOTALE | B4: =GESTIONE!E79 -> 0
A5: NETTO GUARDAROBA | B5: =GUARDAROBA!D16 -> -555
A6: PULIZIE | B6: 500
A7: SIAE | B7: 500
A8: CEDOLINI | B8: 250
A9: CONTABILITA' | B9: 0
A10: ASSUNZIONI SICUREZZA | B10: 0
A11: BONIFICI PERSONALE | B11: 0
A12: COMUNICAZIONE | B12: 0
B21: =SUM(B3:B19) -> 695
A23: RIENTRI E ACCONTI
A25: POS SERATA | B25: =GESTIONE!D56 -> 0
A26: DIREZIONE | B26: 0
A27: POS GUARDAROBA | B27: 0
A28: ONLINE | B28: 0
B32: =SUM(B25:B30) -> 0
A34: RESIDUO CONTANTE | B34: =B21-B32 -> 695

Sheet PRESENZE PERSONALE
A1: 01.01.2025
D34: TOTALE | E34: ='RESOCONTO PROPRIETA'!B11 -> 0
